Exception on /pie/test [GET]
Traceback (most recent call last):
  File "/Users/kratsg/.virtualenvs/django/lib/python2.7/site-packages/flask/app.py", line 1817, in wsgi_app
    response = self.full_dispatch_request()
  File "/Users/kratsg/.virtualenvs/django/lib/python2.7/site-packages/flask/app.py", line 1477, in full_dispatch_request
    rv = self.handle_user_exception(e)
  File "/Users/kratsg/.virtualenvs/django/lib/python2.7/site-packages/flask/app.py", line 1381, in handle_user_exception
    reraise(exc_type, exc_value, tb)
  File "/Users/kratsg/.virtualenvs/django/lib/python2.7/site-packages/flask/app.py", line 1475, in full_dispatch_request
    rv = self.dispatch_request()
  File "/Users/kratsg/.virtualenvs/django/lib/python2.7/site-packages/flask/app.py", line 1461, in dispatch_request
    return self.view_functions[rule.endpoint](**req.view_args)
  File "index.py", line 28, in chart
    output = StringIO.StringIO()
NameError: global name 'StringIO' is not defined
Exception on /pie/test [GET]
Traceback (most recent call last):
  File "/Users/kratsg/.virtualenvs/django/lib/python2.7/site-packages/flask/app.py", line 1817, in wsgi_app
    response = self.full_dispatch_request()
  File "/Users/kratsg/.virtualenvs/django/lib/python2.7/site-packages/flask/app.py", line 1477, in full_dispatch_request
    rv = self.handle_user_exception(e)
  File "/Users/kratsg/.virtualenvs/django/lib/python2.7/site-packages/flask/app.py", line 1381, in handle_user_exception
    reraise(exc_type, exc_value, tb)
  File "/Users/kratsg/.virtualenvs/django/lib/python2.7/site-packages/flask/app.py", line 1475, in full_dispatch_request
    rv = self.dispatch_request()
  File "/Users/kratsg/.virtualenvs/django/lib/python2.7/site-packages/flask/app.py", line 1461, in dispatch_request
    return self.view_functions[rule.endpoint](**req.view_args)
  File "index.py", line 27, in chart
    fig.save_fig(output)
AttributeError: 'Figure' object has no attribute 'save_fig'
